Traceback (most recent call last):
  File "C:\Users\Barry\anaconda3\lib\site-packages\jupyter_cache\executors\utils.py", line 58, in single_nb_execution
    executenb(
  File "C:\Users\Barry\anaconda3\lib\site-packages\nbclient\client.py", line 1204, in execute
    return NotebookClient(nb=nb, resources=resources, km=km, **kwargs).execute()
  File "C:\Users\Barry\anaconda3\lib\site-packages\nbclient\util.py", line 84, in wrapped
    return just_run(coro(*args, **kwargs))
  File "C:\Users\Barry\anaconda3\lib\site-packages\nbclient\util.py", line 62, in just_run
    return loop.run_until_complete(coro)
  File "C:\Users\Barry\anaconda3\lib\asyncio\base_events.py", line 647, in run_until_complete
    return future.result()
  File "C:\Users\Barry\anaconda3\lib\site-packages\nbclient\client.py", line 663, in async_execute
    await self.async_execute_cell(
  File "C:\Users\Barry\anaconda3\lib\site-packages\nbclient\client.py", line 965, in async_execute_cell
    await self._check_raise_for_error(cell, cell_index, exec_reply)
  File "C:\Users\Barry\anaconda3\lib\site-packages\nbclient\client.py", line 862, in _check_raise_for_error
    raise CellExecutionError.from_cell_and_msg(cell, exec_reply_content)
nbclient.exceptions.CellExecutionError: An error occurred while executing the following cell:
------------------
with open(os.path.join(data_dir,"ISMB_TCGA_GE.pkl"), 'rb') as file:
    data = pickle.load(file)
print(data.keys())
------------------

[1;31m---------------------------------------------------------------------------[0m
[1;31mFileNotFoundError[0m                         Traceback (most recent call last)
Input [1;32mIn [3][0m, in [0;36m<cell line: 1>[1;34m()[0m
[1;32m----> 1[0m [38;5;28;01mwith[39;00m [38;5;28;43mopen[39;49m[43m([49m[43mos[49m[38;5;241;43m.[39;49m[43mpath[49m[38;5;241;43m.[39;49m[43mjoin[49m[43m([49m[43mdata_dir[49m[43m,[49m[38;5;124;43m"[39;49m[38;5;124;43mISMB_TCGA_GE.pkl[39;49m[38;5;124;43m"[39;49m[43m)[49m[43m,[49m[43m [49m[38;5;124;43m'[39;49m[38;5;124;43mrb[39;49m[38;5;124;43m'[39;49m[43m)[49m [38;5;28;01mas[39;00m file:
[0;32m      2[0m     data [38;5;241m=[39m pickle[38;5;241m.[39mload(file)
[0;32m      3[0m [38;5;28mprint[39m(data[38;5;241m.[39mkeys())

[1;31mFileNotFoundError[0m: [Errno 2] No such file or directory: '../../ismb_data\\ISMB_TCGA_GE.pkl'
FileNotFoundError: [Errno 2] No such file or directory: '../../ismb_data\\ISMB_TCGA_GE.pkl'

