Traceback (most recent call last):
  File "C:\Users\sebestyenkamp\anaconda3\envs\ismbenv\Lib\site-packages\jupyter_cache\executors\utils.py", line 58, in single_nb_execution
    executenb(
  File "C:\Users\sebestyenkamp\anaconda3\envs\ismbenv\Lib\site-packages\nbclient\client.py", line 1305, in execute
    return NotebookClient(nb=nb, resources=resources, km=km, **kwargs).execute()
           ^^^^^^^^^^^^^^^^^^^^^^^^^^^^^^^^^^^^^^^^^^^^^^^^^^^^^^^^^^^^^^^^^^^^^
  File "C:\Users\sebestyenkamp\anaconda3\envs\ismbenv\Lib\site-packages\jupyter_core\utils\__init__.py", line 173, in wrapped
    return loop.run_until_complete(inner)
           ^^^^^^^^^^^^^^^^^^^^^^^^^^^^^^
  File "C:\Users\sebestyenkamp\anaconda3\envs\ismbenv\Lib\asyncio\base_events.py", line 685, in run_until_complete
    return future.result()
           ^^^^^^^^^^^^^^^
  File "C:\Users\sebestyenkamp\anaconda3\envs\ismbenv\Lib\site-packages\nbclient\client.py", line 705, in async_execute
    await self.async_execute_cell(
  File "C:\Users\sebestyenkamp\anaconda3\envs\ismbenv\Lib\site-packages\nbclient\client.py", line 1058, in async_execute_cell
    await self._check_raise_for_error(cell, cell_index, exec_reply)
  File "C:\Users\sebestyenkamp\anaconda3\envs\ismbenv\Lib\site-packages\nbclient\client.py", line 914, in _check_raise_for_error
    raise CellExecutionError.from_cell_and_msg(cell, exec_reply_content)
nbclient.exceptions.CellExecutionError: An error occurred while executing the following cell:
------------------
# Load the data using pickle
with open('./../data/GCN_Data.pkl' , 'rb') as file : 
    loaded_data = pd.read_pickle(file)
------------------


[1;31m---------------------------------------------------------------------------[0m
[1;31mFileNotFoundError[0m                         Traceback (most recent call last)
Cell [1;32mIn[2], line 2[0m
[0;32m      1[0m [38;5;66;03m# Load the data using pickle[39;00m
[1;32m----> 2[0m [38;5;28;01mwith[39;00m [38;5;28mopen[39m([38;5;124m'[39m[38;5;124m./../data/GCN_Data.pkl[39m[38;5;124m'[39m , [38;5;124m'[39m[38;5;124mrb[39m[38;5;124m'[39m) [38;5;28;01mas[39;00m file : 
[0;32m      3[0m     loaded_data [38;5;241m=[39m pd[38;5;241m.[39mread_pickle(file)

File [1;32m~\anaconda3\envs\ismbenv\Lib\site-packages\IPython\core\interactiveshell.py:310[0m, in [0;36m_modified_open[1;34m(file, *args, **kwargs)[0m
[0;32m    303[0m [38;5;28;01mif[39;00m file [38;5;129;01min[39;00m {[38;5;241m0[39m, [38;5;241m1[39m, [38;5;241m2[39m}:
[0;32m    304[0m     [38;5;28;01mraise[39;00m [38;5;167;01mValueError[39;00m(
[0;32m    305[0m         [38;5;124mf[39m[38;5;124m"[39m[38;5;124mIPython won[39m[38;5;124m'[39m[38;5;124mt let you open fd=[39m[38;5;132;01m{[39;00mfile[38;5;132;01m}[39;00m[38;5;124m by default [39m[38;5;124m"[39m
[0;32m    306[0m         [38;5;124m"[39m[38;5;124mas it is likely to crash IPython. If you know what you are doing, [39m[38;5;124m"[39m
[0;32m    307[0m         [38;5;124m"[39m[38;5;124myou can use builtins[39m[38;5;124m'[39m[38;5;124m open.[39m[38;5;124m"[39m
[0;32m    308[0m     )
[1;32m--> 310[0m [38;5;28;01mreturn[39;00m io_open(file, [38;5;241m*[39margs, [38;5;241m*[39m[38;5;241m*[39mkwargs)

[1;31mFileNotFoundError[0m: [Errno 2] No such file or directory: './../data/GCN_Data.pkl'

